Workbook
Name Slicer_country: #N/A
Name Slicer_Product: #N/A
Name Slicer_Segment__Clean: #N/A
Name Slicer_Year: #N/A

Sheet Dashboard
A1: FINANCIAL PERFORMANCE DASHBOARD Overview of Sales, Expenses, Profitability and Trends | S1: =TODAY() -> 46183

Sheet Pivot Charts

Sheet Pivot Tables
B1: Sales and COGS by Product
B2: Row Labels | C2: Sum of Sales | D2: Sum of COGS | G2: Sales and COGS by Month
B3: Amarilla | C3: 17747116 | D3: 14933012 | G3: Row Labels | H3: Sum of Sales | I3: Sum of COGS
B4: Carretera | C4: 13815308 | D4: 11988503 | G4: January | H4: 6607761.7 | I4: 5793733
B5: Montana | C5: 15555917 | D5: 13417089 | G5: February | H5: 7326401.7 | I5: 6148984
B6: Paseo | C6: 33040014 | D6: 28213706 | G6: March | H6: 5586859.9 | I6: 4916993
B7: Velo | C7: 18250059 | D7: 15944067 | G7: April | H7: 6964775.1 | I7: 6034790.5
B8: VTT | C8: 20670333 | D8: 17477313 | G8: May | H8: 6210211.1 | I8: 5381571
B9: Grand Total | C9: 1.1907875e+08 | D9: 1.0197369e+08 | G9: June | H9: 9842421.8 | I9: 8186181.7
G10: July | H10: 8102920.2 | I10: 7179054.5
B11: Sales and COGS by Country | G11: August | H11: 5864622.4 | I11: 5073556
B12: Row Labels | C12: Sum of Sales | D12: Sum of COGS | G12: September | H12: 10882697 | I12: 9095962
B13: Canada | C13: 24916525 | D13: 21358426 | G13: October | H13: 21671431 | I13: 18231650
B14: France | C14: 24505158 | D14: 20697048 | G14: November | H14: 12651417 | I14: 11281315
B15: Germany | C15: 23677883 | D15: 19842097 | G15: December | H15: 17367229 | I15: 14649899
B16: Mexico | C16: 20949352 | D16: 18041829 | G16: Grand Total | H16: 1.1907875e+08 | I16: 1.0197369e+08
B17: USA | C17: 25029830 | D17: 22034290
B18: Grand Total | C18: 1.1907875e+08 | D18: 1.0197369e+08
B20: Sales and COGS by Segment
B21: Row Labels | C21: Sum of Sales | D21: Sum of COGS
B22: Channel Partners | C22: 1965709.1 | D22: 624832.2
B23: Enterprise | C23: 19611694 | D23: 20226240
B24: Government | C24: 52533131 | D24: 41116088
B25: Midmarket | C25: 2540295.5 | D25: 1721780
B26: Small Business | C26: 42427918 | D26: 38284750
B27: Grand Total | C27: 1.1907875e+08 | D27: 1.0197369e+08

Sheet Slicers

Sheet Analysis
B2: Units Sold | E2: Sale Price | H2: Manufacturing Price | K2: COGS | N2: Total Sales | O2: =SUM(Table1[[ Sales]]) -> 1.1907875e+08
B3: Mean | C3: 1607.4793 | E3: Mean | F3: 118.87088 | H3: Mean | I3: 96.257511 | K3: Mean | L3: 145676.7 | N3: Total COGS | O3: =SUM(Table1[COGS]) -> 1.0197369e+08 | P3: =O3/O2 -> 0.85635507
B4: Standard Error | C4: 32.822482 | E4: Standard Error | F4: 5.1855689 | H4: Standard Error | I4: 4.104781 | K4: Standard Error | L4: 7713.7846 | N4: Total Profit | O4: =SUM(Table1[Profit]) -> 17105059 | P4: =O4/O2 -> 0.14364493
B5: Median | C5: 1540 | E5: Median | F5: 20 | H5: Median | I5: 10 | K5: Median | L5: 22550 | N5: Average Profit Margin | O5: =AVERAGE(Table1[Profit Margin]) -> 0.27961721
B6: Mode | C6: 727 | E6: Mode | F6: 350 | H6: Mode | I6: 10 | K6: Mode | L6: 17430 | N6: Total Units Sold | O6: =SUM(Table1[Units Sold]) -> 1125235.5
B7: Standard Deviation | C7: 867.78074 | E7: Standard Deviation | F7: 136.90295 | H7: Standard Deviation | I7: 108.5247 | K7: Standard Deviation | L7: 203941.73 | N7: Total Discounts | O7: =SUM(Table1[Discounts]) -> 9205248.2 | P7: =O7/O2 -> 0.077303871
B8: Sample Variance | C8: 753043.41 | E8: Sample Variance | F8: 18742.417 | H8: Sample Variance | I8: 11777.61 | K8: Sample Variance | L8: 4.1592229e+10
B9: Kurtosis | C9: -0.31444645 | E9: Kurtosis | F9: -1.1871083 | H9: Kurtosis | I9: -1.4230855 | K9: Kurtosis | L9: 1.6017238
B10: Skewness | C10: 0.43866676 | E10: Skewness | F10: 0.76456836 | H10: Skewness | I10: 0.59673582 | K10: Skewness | L10: 1.5470353 | N10: Product | O10: Sales | P10: % of Total Sales | Q10: COGS | R10: % of Total Sales
B11: Range | C11: 4292.5 | E11: Range | F11: 343 | H11: Range | I11: 257 | K11: Range | L11: 949707 | N11: Carretera | O11: =SUMIF(Data!E:E,Analysis!N11,Data!L:L) -> 13815308 | P11: =O11/$O$17 -> 0.11601825 | Q11: =SUMIF(Data!E:E,Analysis!N11,Data!M:M) -> 11988503 | R11: =Q11/$Q$17 -> 0.11756467
B12: Minimum | C12: 200 | E12: Minimum | F12: 7 | H12: Minimum | I12: 3 | K12: Minimum | L12: 918 | N12: Montana | O12: =SUMIF(Data!E:E,Analysis!N12,Data!L:L) -> 15555917 | P12: =O12/$O$17 -> 0.13063555 | Q12: =SUMIF(Data!E:E,Analysis!N12,Data!M:M) -> 13417089 | R12: =Q12/$Q$17 -> 0.13157402
B13: Maximum | C13: 4492.5 | E13: Maximum | F13: 350 | H13: Maximum | I13: 260 | K13: Maximum | L13: 950625 | N13: Paseo | O13: =SUMIF(Data!E:E,Analysis!N13,Data!L:L) -> 33040014 | P13: =O13/$O$17 -> 0.27746357 | Q13: =SUMIF(Data!E:E,Analysis!N13,Data!M:M) -> 28213706 | R13: =Q13/$Q$17 -> 0.27667633
B14: Sum | C14: 1123628 | E14: Sum | F14: 82853 | H14: Sum | I14: 67284 | K14: Sum | L14: 101828013 | N14: Velo | O14: =SUMIF(Data!E:E,Analysis!N14,Data!L:L) -> 18250059 | P14: =O14/$O$17 -> 0.15326042 | Q14: =SUMIF(Data!E:E,Analysis!N14,Data!M:M) -> 15944067 | R14: =Q14/$Q$17 -> 0.15635471
B15: Count | C15: 699 | E15: Count | F15: 697 | H15: Count | I15: 699 | K15: Count | L15: 699 | N15: VTT | O15: =SUMIF(Data!E:E,Analysis!N15,Data!L:L) -> 20670333 | P15: =O15/$O$17 -> 0.17358541 | Q15: =SUMIF(Data!E:E,Analysis!N15,Data!M:M) -> 17477313 | R15: =Q15/$Q$17 -> 0.17139042
N16: Amarilla | O16: =SUMIF(Data!E:E,Analysis!N16,Data!L:L) -> 17747116 | P16: =O16/$O$17 -> 0.1490368 | Q16: =SUMIF(Data!E:E,Analysis!N16,Data!M:M) -> 14933012 | R16: =Q16/$Q$17 -> 0.14643985
B17: Segment (Clean) | C17: Count | E17: Country (Clean) | F17: Count | H17: Product | I17: Count | K17: Discount Band | L17: Count | N17: Total | O17: =SUM(O11:O16) -> 1.1907875e+08 | P17: =SUM(P11:P16) -> 1 | Q17: =SUM(Q11:Q16) -> 1.0197369e+08 | R17: =SUM(R11:R16) -> 1
B18: Government | C18: =COUNTIF(Table1[Segment (Clean)],Analysis!B18) -> 300 | E18: Canada | F18: =COUNTIF(Table1[Country (Clean)],Analysis!E18) -> 140 | H18: Carretera | I18: =COUNTIF(Table1[Product],Analysis!H18) -> 93 | K18: None | L18: =COUNTIF(Table1[Discount Band],Analysis!K18) -> 53
B19: Midmarket | C19: =COUNTIF(Table1[Segment (Clean)],Analysis!B19) -> 100 | E19: Germany | F19: =COUNTIF(Table1[Country (Clean)],Analysis!E19) -> 140 | H19: Montana | I19: =COUNTIF(Table1[Product],Analysis!H19) -> 93 | K19: Low | L19: =COUNTIF(Table1[Discount Band],Analysis!K19) -> 160 | N19: Country | O19: Sales | P19: % of Total Sales | Q19: COGS | R19: % of Total Sales
B20: Channel Partners | C20: =COUNTIF(Table1[Segment (Clean)],Analysis!B20) -> 100 | E20: France | F20: =COUNTIF(Table1[Country (Clean)],Analysis!E20) -> 140 | H20: Paseo | I20: =COUNTIF(Table1[Product],Analysis!H20) -> 202 | K20: Medium | L20: =COUNTIF(Table1[Discount Band],Analysis!K20) -> 242 | N20: Canada | O20: =SUMIF(Data!C:C,Analysis!N20,Data!L:L) -> 24916525 | P20: =O20/$O$25 -> 0.2092441 | Q20: =SUMIF(Data!C:C,Analysis!N20,Data!M:M) -> 21358426 | R20: =Q20/$Q$25 -> 0.20945036
B21: Enterprise | C21: =COUNTIF(Table1[Segment (Clean)],Analysis!B21) -> 100 | E21: Mexico | F21: =COUNTIF(Table1[Country (Clean)],Analysis!E21) -> 140 | H21: Velo | I21: =COUNTIF(Table1[Product],Analysis!H21) -> 109 | K21: High | L21: =COUNTIF(Table1[Discount Band],Analysis!K21) -> 245 | N21: Germany | O21: =SUMIF(Data!C:C,Analysis!N21,Data!L:L) -> 23677883 | P21: =O21/$O$25 -> 0.19884222 | Q21: =SUMIF(Data!C:C,Analysis!N21,Data!M:M) -> 19842097 | R21: =Q21/$Q$25 -> 0.19458055
B22: Small Business | C22: =COUNTIF(Table1[Segment (Clean)],Analysis!B22) -> 100 | E22: United States Of America | F22: =COUNTIF(Table1[Country (Clean)],Analysis!E22) -> 0 | H22: VTT | I22: =COUNTIF(Table1[Product],Analysis!H22) -> 109 | L22: =COUNTIF(Table1[Discount Band],"") -> 0 | N22: France | O22: =SUMIF(Data!C:C,Analysis!N22,Data!L:L) -> 24505158 | P22: =O22/$O$25 -> 0.20578951 | Q22: =SUMIF(Data!C:C,Analysis!N22,Data!M:M) -> 20697048 | R22: =Q22/$Q$25 -> 0.20296459
C23: =COUNTIF(Table1[Segment (Clean)],"") -> 0 | F23: =COUNTIF(Table1[Country (Clean)],"") -> 0 | H23: Amarilla | I23: =COUNTIF(Table1[Product],Analysis!H23) -> 94 | K23: Total | L23: =SUM(L18:L22) -> 700 | N23: Mexico | O23: =SUMIF(Data!C:C,Analysis!N23,Data!L:L) -> 20949352 | P23: =O23/$O$25 -> 0.17592855 | Q23: =SUMIF(Data!C:C,Analysis!N23,Data!M:M) -> 18041829 | R23: =Q23/$Q$25 -> 0.17692631
B24: Total | C24: =SUM(C18:C23) -> 700 | E24: Total | F24: =SUM(F18:F23) -> 560 | I24: =COUNTIF(Table1[Product],"") -> 0 | N24: USA | O24: =SUMIF(Data!C:C,Analysis!N24,Data!L:L) -> 25029830 | P24: =O24/$O$25 -> 0.21019561 | Q24: =SUMIF(Data!C:C,Analysis!N24,Data!M:M) -> 22034290 | R24: =Q24/$Q$25 -> 0.21607818
H25: Total | I25: =SUM(I18:I24) -> 700 | N25: Total | O25: =SUM(O20:O24) -> 1.1907875e+08 | P25: =SUM(P20:P24) -> 1 | Q25: =SUM(Q20:Q24) -> 1.0197369e+08 | R25: =SUM(R20:R24) -> 1
N27: Segment (Clean) | O27: Sales | P27: % of Total Sales | Q27: COGS | R27: % of Total Sales
N28: Government | O28: =SUMIF(Data!B:B,Analysis!N28,Data!L:L) -> 52533131 | P28: =O28/$O$33 -> 0.44116294 | Q28: =SUMIF(Data!B:B,Analysis!N28,Data!M:M) -> 41116088 | R28: =Q28/$Q$33 -> 0.4032029
N29: Midmarket | O29: =SUMIF(Data!B:B,Analysis!N29,Data!L:L) -> 2540295.5 | P29: =O29/$O$33 -> 0.021332904 | Q29: =SUMIF(Data!B:B,Analysis!N29,Data!M:M) -> 1721780 | R29: =Q29/$Q$33 -> 0.016884551
N30: Channel Partners | O30: =SUMIF(Data!B:B,Analysis!N30,Data!L:L) -> 1965709.1 | P30: =O30/$O$33 -> 0.01650764 | Q30: =SUMIF(Data!B:B,Analysis!N30,Data!M:M) -> 624832.2 | R30: =Q30/$Q$33 -> 0.0061273864
N31: Enterprise | O31: =SUMIF(Data!B:B,Analysis!N31,Data!L:L) -> 19611694 | P31: =O31/$O$33 -> 0.16469517 | Q31: =SUMIF(Data!B:B,Analysis!N31,Data!M:M) -> 20226240 | R31: =Q31/$Q$33 -> 0.19834763
N32: Small Business | O32: =SUMIF(Data!B:B,Analysis!N32,Data!L:L) -> 42427918 | P32: =O32/$O$33 -> 0.35630135 | Q32: =SUMIF(Data!B:B,Analysis!N32,Data!M:M) -> 38284750 | R32: =Q32/$Q$33 -> 0.37543753
N33: Total | O33: =SUM(O28:O32) -> 1.1907875e+08 | P33: =SUM(P28:P32) -> 1 | Q33: =SUM(Q28:Q32) -> 1.0197369e+08 | R33: =SUM(R28:R32) -> 1

Sheet Data
A1: segment | B1: Segment (Clean) | C1: Country | D1: Country (Clean) | E1: Product | F1: Discount Band | G1: Units Sold | H1: Manufacturing Price | I1: Sale Price | J1: Gross Sales | K1: Discounts | L1: Sales | M1: COGS | N1: Profit | O1: Profit Margin | P1: Date | Q1: Month Number | R1: Month Name | S1: Year
A2: Government | B2: =PROPER(A2) -> Government | C2: Canada | D2: =PROPER(Table1[[#This Row],[Country]]) -> Canada | E2: Carretera | F2: None | G2: 1618.5 | H2: 3 | I2: 20 | J2: =G2*I2 -> 32370 | K2: 0 | L2: =J2-K2 -> 32370 | M2: 16185 | N2: =L2-M2 -> 16185 | O2: =N2/L2 -> 0.5 | P2: 41640 | Q2: =MONTH(P2) -> 1 | R2: =TEXT(P2,"mmmm") -> January | S2: =YEAR(P2) -> 2014
A3: Government | B3: =PROPER(A3) -> Government | C3: Germany | D3: =PROPER(Table1[[#This Row],[Country]]) -> Germany | E3: Carretera | F3: None | G3: 1321 | H3: 3 | I3: 20 | J3: =G3*I3 -> 26420 | K3: 0 | L3: =J3-K3 -> 26420 | M3: 13210 | N3: =L3-M3 -> 13210 | O3: =N3/L3 -> 0.5 | P3: 41640 | Q3: =MONTH(P3) -> 1 | R3: =TEXT(P3,"mmmm") -> January | S3: =YEAR(P3) -> 2014
A4: Midmarket | B4: =PROPER(A4) -> Midmarket | C4: France | D4: =PROPER(Table1[[#This Row],[Country]]) -> France | E4: Carretera | F4: None | G4: 2178 | H4: 3 | I4: 15 | J4: =G4*I4 -> 32670 | K4: 0 | L4: =J4-K4 -> 32670 | M4: 21780 | N4: =L4-M4 -> 10890 | O4: =N4/L4 -> 0.33333333 | P4: 41791 | Q4: =MONTH(P4) -> 6 | R4: =TEXT(P4,"mmmm") -> June | S4: =YEAR(P4) -> 2014
A5: Midmarket | B5: =PROPER(A5) -> Midmarket | C5: Germany | D5: =PROPER(Table1[[#This Row],[Country]]) -> Germany | E5: Carretera | F5: None | G5: 888 | H5: 3 | I5: 15 | J5: =G5*I5 -> 13320 | K5: 0 | L5: =J5-K5 -> 13320 | M5: 8880 | N5: =L5-M5 -> 4440 | O5: =N5/L5 -> 0.33333333 | P5: 41791 | Q5: =MONTH(P5) -> 6 | R5: =TEXT(P5,"mmmm") -> June | S5: =YEAR(P5) -> 2014
A6: Midmarket | B6: =PROPER(A6) -> Midmarket | C6: Mexico | D6: =PROPER(Table1[[#This Row],[Country]]) -> Mexico | E6: Carretera | F6: None | G6: 2470 | H6: 3 | I6: 15 | J6: =G6*I6 -> 37050 | K6: 0 | L6: =J6-K6 -> 37050 | M6: 24700 | N6: =L6-M6 -> 12350 | O6: =N6/L6 -> 0.33333333 | P6: 41791 | Q6: =MONTH(P6) -> 6 | R6: =TEXT(P6,"mmmm") -> June | S6: =YEAR(P6) -> 2014
A7: Government | B7: =PROPER(A7) -> Government | C7: Germany | D7: =PROPER(Table1[[#This Row],[Country]]) -> Germany | E7: Carretera | F7: None | G7: 1513 | H7: 3 | I7: 350 | J7: =G7*I7 -> 529550 | K7: 0 | L7: =J7-K7 -> 529550 | M7: 393380 | N7: =L7-M7 -> 136170 | O7: =N7/L7 -> 0.25714286 | P7: 41974 | Q7: =MONTH(P7) -> 12 | R7: =TEXT(P7,"mmmm") -> December | S7: =YEAR(P7) -> 2014
A8: Midmarket | B8: =PROPER(A8) -> Midmarket | C8: Germany | D8: =PROPER(Table1[[#This Row],[Country]]) -> Germany | E8: Montana | F8: None | G8: 921 | H8: 5 | I8: 15 | J8: =G8*I8 -> 13815 | K8: 0 | L8: =J8-K8 -> 13815 | M8: 9210 | N8: =L8-M8 -> 4605 | O8: =N8/L8 -> 0.33333333 | P8: 41699 | Q8: =MONTH(P8) -> 3 | R8: =TEXT(P8,"mmmm") -> March | S8: =YEAR(P8) -> 2014
A9: Channel Partners | B9: =PROPER(A9) -> Channel Partners | C9: Canada | D9: =PROPER(Table1[[#This Row],[Country]]) -> Canada | E9: Montana | F9: None | G9: 2518 | H9: 5 | I9: 12 | J9: =G9*I9 -> 30216 | K9: 0 | L9: =J9-K9 -> 30216 | M9: 7554 | N9: =L9-M9 -> 22662 | O9: =N9/L9 -> 0.75 | P9: 41791 | Q9: =MONTH(P9) -> 6 | R9: =TEXT(P9,"mmmm") -> June | S9: =YEAR(P9) -> 2014
A10: Government | B10: =PROPER(A10) -> Government | C10: France | D10: =PROPER(Table1[[#This Row],[Country]]) -> France | E10: Montana | F10: None | G10: 1899 | H10: 5 | I10: 20 | J10: =G10*I10 -> 37980 | K10: 0 | L10: =J10-K10 -> 37980 | M10: 18990 | N10: =L10-M10 -> 18990 | O10: =N10/L10 -> 0.5 | P10: 41791 | Q10: =MONTH(P10) -> 6 | R10: =TEXT(P10,"mmmm") -> June | S10: =YEAR(P10) -> 2014
A11: Channel Partners | B11: =PROPER(A11) -> Channel Partners | C11: France | D11: =PROPER(Table1[[#This Row],[Country]]) -> France | E11: Montana | F11: None | G11: 1545 | H11: 5 | I11: =Analysis!$F$3 -> 118.87088 | J11: =G11*I11 -> 183655.5 | K11: 0 | L11: =J11-K11 -> 183655.5 | M11: =Analysis!$L$3 -> 145676.7 | N11: =L11-M11 -> 37978.803 | O11: =N11/L11 -> 0.20679371 | P11: 41791 | Q11: =MONTH(P11) -> 6 | R11: =TEXT(P11,"mmmm") -> June | S11: =YEAR(P11) -> 2014
A12: Midmarket | B12: =PROPER(A12) -> Midmarket | C12: Mexico | D12: =PROPER(Table1[[#This Row],[Country]]) -> Mexico | E12: Montana | F12: None | G12: 2470 | H12: 5 | I12: 15 | J12: =G12*I12 -> 37050 | K12: 0 | L12: =J12-K12 -> 37050 | M12: 24700 | N12: =L12-M12 -> 12350 | O12: =N12/L12 -> 0.33333333 | P12: 41791 | Q12: =MONTH(P12) -> 6 | R12: =TEXT(P12,"mmmm") -> June | S12: =YEAR(P12) -> 2014
A13: Enterprise | B13: =PROPER(A13) -> Enterprise | C13: Canada | D13: =PROPER(Table1[[#This Row],[Country]]) -> Canada | E13: Montana | F13: None | G13: 2665.5 | H13: 5 | I13: 125 | J13: =G13*I13 -> 333187.5 | K13: 0 | L13: =J13-K13 -> 333187.5 | M13: 319860 | N13: =L13-M13 -> 13327.5 | O13: =N13/L13 -> 0.04 | P13: 41821 | Q13: =MONTH(P13) -> 7 | R13: =TEXT(P13,"mmmm") -> July | S13: =YEAR(P13) -> 2014
A14: small business | B14: =PROPER(A14) -> Small Business | C14: mexico | D14: =PROPER(Table1[[#This Row],[Country]]) -> Mexico | E14: Montana | F14: None | G14: 958 | H14: 5 | I14: 300 | J14: =G14*I14 -> 287400 | K14: 0 | L14: =J14-K14 -> 287400 | M14: 239500 | N14: =L14-M14 -> 47900 | O14: =N14/L14 -> 0.16666667 | P14: 41852 | Q14: =MONTH(P14) -> 8 | R14: =TEXT(P14,"mmmm") -> August | S14: =YEAR(P14) -> 2014
A15: Government | B15: =PROPER(A15) -> Government | C15: Germany | D15: =PROPER(Table1[[#This Row],[Country]]) -> Germany | E15: Montana | F15: None | G15: 2146 | H15: 5 | I15: 7 | J15: =G15*I15 -> 15022 | K15: 0 | L15: =J15-K15 -> 15022 | M15: 10730 | N15: =L15-M15 -> 4292 | O15: =N15/L15 -> 0.28571429 | P15: 41883 | Q15: =MONTH(P15) -> 9 | R15: =TEXT(P15,"mmmm") -> September | S15: =YEAR(P15) -> 2014
A16: Enterprise | B16: =PROPER(A16) -> Enterprise | C16: Canada | D16: =PROPER(Table1[[#This Row],[Country]]) -> Canada | E16: Montana | F16: None | G16: 345 | H16: 5 | I16: 125 | J16: =G16*I16 -> 43125 | K16: 0 | L16: =J16-K16 -> 43125 | M16: 41400 | N16: =L16-M16 -> 1725 | O16: =N16/L16 -> 0.04 | P16: 41548 | Q16: =MONTH(P16) -> 10 | R16: =TEXT(P16,"mmmm") -> October | S16: =YEAR(P16) -> 2013
A17: Midmarket | B17: =PROPER(A17) -> Midmarket | C17: USA | D17: =PROPER(Table1[[#This Row],[Country]]) -> Usa | E17: Montana | F17: None | G17: 615 | H17: 5 | I17: 15 | J17: =G17*I17 -> 9225 | K17: 0 | L17: =J17-K17 -> 9225 | M17: 6150 | N17: =L17-M17 -> 3075 | O17: =N17/L17 -> 0.33333333 | P17: 41974 | Q17: =MONTH(P17) -> 12 | R17: =TEXT(P17,"mmmm") -> December | S17: =YEAR(P17) -> 2014
A18: Government | B18: =PROPER(A18) -> Government | C18: Canada | D18: =PROPER(Table1[[#This Row],[Country]]) -> Canada | E18: Paseo | F18: None | G18: 292 | H18: 10 | I18: =Analysis!$F$3 -> 118.87088 | J18: =G18*I18 -> 34710.296 | K18: 0 | L18: =J18-K18 -> 34710.296 | M18: 2920 | N18: =L18-M18 -> 31790.296 | O18: =N18/L18 -> 0.9158751 | P18: 41671 | Q18: =MONTH(P18) -> 2 | R18: =TEXT(P18,"mmmm") -> February | S18: =YEAR(P18) -> 2014
A19: Midmarket | B19: =PROPER(A19) -> Midmarket | C19: Mexico | D19: =PROPER(Table1[[#This Row],[Country]]) -> Mexico | E19: Paseo | F19: None | G19: 974 | H19: 10 | I19: 15 | J19: =G19*I19 -> 14610 | K19: 0 | L19: =J19-K19 -> 14610 | M19: 9740 | N19: =L19-M19 -> 4870 | O19: =N19/L19 -> 0.33333333 | P19: 41671 | Q19: =MONTH(P19) -> 2 | R19: =TEXT(P19,"mmmm") -> February | S19: =YEAR(P19) -> 2014
A20: Channel Partners | B20: =PROPER(A20) -> Channel Partners | C20: Canada | D20: =PROPER(Table1[[#This Row],[Country]]) -> Canada | E20: Paseo | F20: None | G20: 2518 | H20: 10 | I20: 12 | J20: =G20*I20 -> 30216 | K20: 0 | L20: =J20-K20 -> 30216 | M20: 7554 | N20: =L20-M20 -> 22662 | O20: =N20/L20 -> 0.75 | P20: 41791 | Q20: =MONTH(P20) -> 6 | R20: =TEXT(P20,"mmmm") -> June | S20: =YEAR(P20) -> 2014
A21: Government | B21: =PROPER(A21) -> Government | C21: Germany | D21: =PROPER(Table1[[#This Row],[Country]]) -> Germany | E21: Paseo | F21: None | G21: 1006 | H21: 10 | I21: 350 | J21: =G21*I21 -> 352100 | K21: 0 | L21: =J21-K21 -> 352100 | M21: 261560 | N21: =L21-M21 -> 90540 | O21: =N21/L21 -> 0.25714286 | P21: 41791 | Q21: =MONTH(P21) -> 6 | R21: =TEXT(P21,"mmmm") -> June | S21: =YEAR(P21) -> 2014
A22: Channel Partners | B22: =PROPER(A22) -> Channel Partners | C22: Germany | D22: =PROPER(Table1[[#This Row],[Country]]) -> Germany | E22: Paseo | F22: None | G22: 367 | H22: 10 | I22: 12 | J22: =G22*I22 -> 4404 | K22: 0 | L22: =J22-K22 -> 4404 | M22: 1101 | N22: =L22-M22 -> 3303 | O22: =N22/L22 -> 0.75 | P22: 41821 | Q22: =MONTH(P22) -> 7 | R22: =TEXT(P22,"mmmm") -> July | S22: =YEAR(P22) -> 2014
A23: Government | B23: =PROPER(A23) -> Government | C23: Mexico | D23: =PROPER(Table1[[#This Row],[Country]]) -> Mexico | E23: Paseo | F23: None | G23: 883 | H23: 10 | I23: 7 | J23: =G23*I23 -> 6181 | K23: 0 | L23: =J23-K23 -> 6181 | M23: 4415 | N23: =L23-M23 -> 1766 | O23: =N23/L23 -> 0.28571429 | P23: 41852 | Q23: =MONTH(P23) -> 8 | R23: =TEXT(P23,"mmmm") -> August | S23: =YEAR(P23) -> 2014
A24: Midmarket | B24: =PROPER(A24) -> Midmarket | C24: France | D24: =PROPER(Table1[[#This Row],[Country]]) -> France | E24: Paseo | F24: None | G24: 549 | H24: 10 | I24: 15 | J24: =G24*I24 -> 8235 | K24: 0 | L24: =J24-K24 -> 8235 | M24: 5490 | N24: =L24-M24 -> 2745 | O24: =N24/L24 -> 0.33333333 | P24: 41518 | Q24: =MONTH(P24) -> 9 | R24: =TEXT(P24,"mmmm") -> September | S24: =YEAR(P24) -> 2013
A25: Small Business | B25: =PROPER(A25) -> Small Business | C25: Mexico | D25: =PROPER(Table1[[#This Row],[Country]]) -> Mexico | E25: Paseo | F25: None | G25: 788 | H25: 10 | I25: 300 | J25: =G25*I25 -> 236400 | K25: 0 | L25: =J25-K25 -> 236400 | M25: 197000 | N25: =L25-M25 -> 39400 | O25: =N25/L25 -> 0.16666667 | P25: 41518 | Q25: =MONTH(P25) -> 9 | R25: =TEXT(P25,"mmmm") -> September | S25: =YEAR(P25) -> 2013
A26: Midmarket | B26: =PROPER(A26) -> Midmarket | C26: Mexico | D26: =PROPER(Table1[[#This Row],[Country]]) -> Mexico | E26: Paseo | F26: None | G26: 2472 | H26: 10 | I26: 15 | J26: =G26*I26 -> 37080 | K26: 0 | L26: =J26-K26 -> 37080 | M26: 24720 | N26: =L26-M26 -> 12360 | O26: =N26/L26 -> 0.33333333 | P26: 41883 | Q26: =MONTH(P26) -> 9 | R26: =TEXT(P26,"mmmm") -> September | S26: =YEAR(P26) -> 2014
A27: Government | B27: =PROPER(A27) -> Government | C27: USA | D27: =PROPER(Table1[[#This Row],[Country]]) -> Usa | E27: Paseo | F27: None | G27: 1143 | H27: 10 | I27: 7 | J27: =G27*I27 -> 8001 | K27: 0 | L27: =J27-K27 -> 8001 | M27: 5715 | N27: =L27-M27 -> 2286 | O27: =N27/L27 -> 0.28571429 | P27: 41913 | Q27: =MONTH(P27) -> 10 | R27: =TEXT(P27,"mmmm") -> October | S27: =YEAR(P27) -> 2014
A28: Government | B28: =PROPER(A28) -> Government | C28: Canada | D28: =PROPER(Table1[[#This Row],[Country]]) -> Canada | E28: Paseo | F28: None | G28: 1725 | H28: 10 | I28: 350 | J28: =G28*I28 -> 603750 | K28: 0 | L28: =J28-K28 -> 603750 | M28: 448500 | N28: =L28-M28 -> 155250 | O28: =N28/L28 -> 0.25714286 | P28: 41579 | Q28: =MONTH(P28) -> 11 | R28: =TEXT(P28,"mmmm") -> November | S28: =YEAR(P28) -> 2013
A29: Channel Partners | B29: =PROPER(A29) -> Channel Partners | C29: USA | D29: =PROPER(Table1[[#This Row],[Country]]) -> Usa | E29: Paseo | F29: None | G29: 912 | H29: 10 | I29: 12 | J29: =G29*I29 -> 10944 | K29: 0 | L29: =J29-K29 -> 10944 | M29: 2736 | N29: =L29-M29 -> 8208 | O29: =N29/L29 -> 0.75 | P29: 41579 | Q29: =MONTH(P29) -> 11 | R29: =TEXT(P29,"mmmm") -> November | S29: =YEAR(P29) -> 2013
A30: Midmarket | B30: =PROPER(A30) -> Midmarket | C30: Canada | D30: =PROPER(Table1[[#This Row],[Country]]) -> Canada | E30: Paseo | F30: None | G30: 2152 | H30: 10 | I30: 15 | J30: =G30*I30 -> 32280 | K30: 0 | L30: =J30-K30 -> 32280 | M30: 21520 | N30: =L30-M30 -> 10760 | O30: =N30/L30 -> 0.33333333 | P30: 41609 | Q30: =MONTH(P30) -> 12 | R30: =TEXT(P30,"mmmm") -> December | S30: =YEAR(P30) -> 2013
... A41: Channel Partners | B41: =PROPER(A41) -> Channel Partners | C41: Germany | D41: =PROPER(Table1[[#This Row],[Country]]) -> Germany | E41: VTT | F41: None | G41: 2838 | H41: 250 | I41: 12 | J41: =G41*I41 -> 34056 | K41: 0 | L41: =J41-K41 -> 34056 | M41: 8514 | N41: =L41-M41 -> 25542 | O41: =N41/L41 -> 0.75 | P41: 41730 | Q41: =MONTH(P41) -> 4 | R41: =TEXT(P41,"mmmm") -> April | S41: =YEAR(P41) -> 2014
A42: Midmarket | B42: =PROPER(A42) -> Midmarket | C42: Germany | D42: =PROPER(Table1[[#This Row],[Country]]) -> Germany | E42: VTT | F42: None | G42: =Analysis!C3 -> 1607.4793 | H42: =Analysis!I3 -> 96.257511 | I42: =Analysis!$F$3 -> 118.87088 | J42: =G42*I42 -> 191082.47 | K42: 0 | L42: =J42-K42 -> 191082.47 | M42: 21780 | N42: =L42-M42 -> 169302.47 | O42: =N42/L42 -> 0.8860178 | P42: 41791 | Q42: =MONTH(P42) -> 6 | R42: =TEXT(P42,"mmmm") -> June | S42: =YEAR(P42) -> 2014
A43: Midmarket | B43: =PROPER(A43) -> Midmarket | C43: Germany | D43: =PROPER(Table1[[#This Row],[Country]]) -> Germany | E43: VTT | F43: None | G43: 888 | H43: 250 | I43: 15 | J43: =G43*I43 -> 13320 | K43: 0 | L43: =J43-K43 -> 13320 | M43: 8880 | N43: =L43-M43 -> 4440 | O43: =N43/L43 -> 0.33333333 | P43: 41791 | Q43: =MONTH(P43) -> 6 | R43: =TEXT(P43,"mmmm") -> June | S43: =YEAR(P43) -> 2014
A44: Government | B44: =PROPER(A44) -> Government | C44: France | D44: =PROPER(Table1[[#This Row],[Country]]) -> France | E44: VTT | F44: None | G44: 1527 | H44: 250 | I44: 350 | J44: =G44*I44 -> 534450 | K44: 0 | L44: =J44-K44 -> 534450 | M44: 397020 | N44: =L44-M44 -> 137430 | O44: =N44/L44 -> 0.25714286 | P44: 41518 | Q44: =MONTH(P44) -> 9 | R44: =TEXT(P44,"mmmm") -> September | S44: =YEAR(P44) -> 2013
A45: Small Business | B45: =PROPER(A45) -> Small Business | C45: France | D45: =PROPER(Table1[[#This Row],[Country]]) -> France | E45: VTT | F45: None | G45: 2151 | H45: 250 | I45: 300 | J45: =G45*I45 -> 645300 | K45: 0 | L45: =J45-K45 -> 645300 | M45: 537750 | N45: =L45-M45 -> 107550 | O45: =N45/L45 -> 0.16666667 | P45: 41883 | Q45: =MONTH(P45) -> 9 | R45: =TEXT(P45,"mmmm") -> September | S45: =YEAR(P45) -> 2014
A46: Government | B46: =PROPER(A46) -> Government | C46: Canada | D46: =PROPER(Table1[[#This Row],[Country]]) -> Canada | E46: VTT | F46: None | G46: 1817 | H46: 250 | I46: 20 | J46: =G46*I46 -> 36340 | K46: 0 | L46: =J46-K46 -> 36340 | M46: 18170 | N46: =L46-M46 -> 18170 | O46: =N46/L46 -> 0.5 | P46: 41974 | Q46: =MONTH(P46) -> 12 | R46: =TEXT(P46,"mmmm") -> December | S46: =YEAR(P46) -> 2014
A47: Government | B47: =PROPER(A47) -> Government | C47: France | D47: =PROPER(Table1[[#This Row],[Country]]) -> France | E47: Amarilla | F47: None | G47: 2750 | H47: 260 | I47: 350 | J47: =G47*I47 -> 962500 | K47: 0 | L47: =J47-K47 -> 962500 | M47: 715000 | N47: =L47-M47 -> 247500 | O47: =N47/L47 -> 0.25714286 | P47: 41671 | Q47: =MONTH(P47) -> 2 | R47: =TEXT(P47,"mmmm") -> February | S47: =YEAR(P47) -> 2014
A48: Channel Partners | B48: =PROPER(A48) -> Channel Partners | C48: USA | D48: =PROPER(Table1[[#This Row],[Country]]) -> Usa | E48: Amarilla | F48: None | G48: 1953 | H48: 260 | I48: 12 | J48: =G48*I48 -> 23436 | K48: 0 | L48: =J48-K48 -> 23436 | M48: 5859 | N48: =L48-M48 -> 17577 | O48: =N48/L48 -> 0.75 | P48: 41730 | Q48: =MONTH(P48) -> 4 | R48: =TEXT(P48,"mmmm") -> April | S48: =YEAR(P48) -> 2014
A49: Enterprise | B49: =PROPER(A49) -> Enterprise | C49: Germany | D49: =PROPER(Table1[[#This Row],[Country]]) -> Germany | E49: Amarilla | F49: None | G49: 4219.5 | H49: 260 | I49: 125 | J49: =G49*I49 -> 527437.5 | K49: 0 | L49: =J49-K49 -> 527437.5 | M49: 506340 | N49: =L49-M49 -> 21097.5 | O49: =N49/L49 -> 0.04 | P49: 41730 | Q49: =MONTH(P49) -> 4 | R49: =TEXT(P49,"mmmm") -> April | S49: =YEAR(P49) -> 2014
A50: Government | B50: =PROPER(A50) -> Government | C50: France | D50: =PROPER(Table1[[#This Row],[Country]]) -> France | E50: Amarilla | F50: None | G50: 1899 | H50: 260 | I50: 20 | J50: =G50*I50 -> 37980 | K50: 0 | L50: =J50-K50 -> 37980 | M50: 18990 | N50: =L50-M50 -> 18990 | O50: =N50/L50 -> 0.5 | P50: 41791 | Q50: =MONTH(P50) -> 6 | R50: =TEXT(P50,"mmmm") -> June | S50: =YEAR(P50) -> 2014
...
